Workbook
Name RentabilidadeAnual: 'Parâmetros'!$C$5
Name TaxaMensal: 'Parâmetros'!$C$6
Name AporteInicial: 'Parâmetros'!$C$7
Name AporteMensal: 'Parâmetros'!$C$8
Name ValorFII: 'Parâmetros'!$C$9
Name DividendYield: 'Parâmetros'!$C$10
Name Perfil: 'Parâmetros'!$C$11
Name PercentualInvestido: 'Parâmetros'!$C$12
Name SalarioMinimo: 'Parâmetros'!$C$13
Name CenarioAnos: 'Parâmetros'!$C$17
Name CenarioDY: 'Parâmetros'!$C$18
Name CenarioTaxa: 'Parâmetros'!$C$19
Name CenarioTaxaMensal: 'Parâmetros'!$C$20
Name UsarReserva: 'Parâmetros'!$C$21
Name TabelaPerfis: Perfis!$B$4:$D$7
Name Anos: Simulador!$B$17:$B$46
Name Aportes: Simulador!$C$17:$C$46
Name PatrimonioEstimado: Simulador!$D$17:$D$46
Name DividendosNoAno: Simulador!$E$17:$E$46
Name DividendosAcumulados: Simulador!$F$17:$F$46
Name FatorDesconto: Simulador!$G$17:$G$46
Name DividendosPV: Simulador!$H$17:$H$46
Name DividendosAcumPV: Simulador!$I$17:$I$46
Name AporteDoPerfil: Simulador!$C$7
Name AporteInvestido: Simulador!$C$9
Name ReservaMensal: Simulador!$C$10
Name EnvelopeReserva: Simulador!$C$11
Name EnvelopeInvestido: Simulador!$C$13
Name AporteInicialInvestido: Simulador!$C$14

Sheet Instruções
B2: CONTROLE DE INVESTIMENTOS EM FIIs — FERRAMENTA NO EXCEL
B3: Desafio de Projeto • Criando uma Ferramenta de Controle de Investimentos com Excel • Santander Excel 2026 / DIO
B5: O QUE A FERRAMENTA FAZ
B6: • Transforma o seu aporte mensal em uma projeção de patrimônio e de renda (dividendos) com FIIs.
B7: • Calcula o patrimônio com a função VF (valor futuro) e projeta a renda ano a ano, de 2 a 30 anos.
B8: • Divide o aporte conforme o seu perfil de investidor usando PROCV + tabela de apoio (aba Perfis).
B9: • Compara cenários: mudando horizonte, Dividend Yield e rentabilidade, os números recalculam.
B10: • Separa uma reserva de oportunidade (P4) para comprar FIIs nas quedas e mostra o ganho dela.
B12: PERGUNTAS DE NEGÓCIO — RESPOSTAS AO VIVO (ligadas ao Simulador)
B13: Pergunta | C13: Resposta | D13: Formato/onde
B14: Quanto do meu aporte mensal vai para os FIIs? | C14: =Simulador!$C$9 | D14: aporte do perfil × P4
B15: Quanto do meu aporte fica na reserva de oportunidade? | C15: =Simulador!$C$10 | D15: P4 complementar
B16: Qual é o patrimônio projetado no horizonte escolhido? | C16: =Simulador!$D$60 | D16: VF do cenário
B17: Quantos dividendos eu recebo no último ano do horizonte? | C17: =Simulador!$L$21 | D17: SOMASE por ano
B18: E por mês, quanto isso representa? | C18: =Simulador!$L$22 | D18: ÷ 12
B19: Isso equivale a quantos salários mínimos por mês? | C19: =Simulador!$L$23 | D19: régua prática
B20: Quanto valem hoje os dividendos de todo o horizonte? | C20: =Simulador!$L$24 | D20: SOMARPRODUTO (VP)
B21: Quanto de dividendos eu terei acumulado até lá? | C21: =Simulador!$L$26 | D21: SOMASE acumulado
B22: Quanto a reserva de oportunidade agrega de patrimônio? | C22: =Simulador!$D$61 | D22: S vs N
B23: Qual é o retorno total projetado sobre o valor investido? | C23: =Simulador!$D$62 | D23: patrimônio ÷ investido − 1
B24: Quanto de renda mensal a carteira geraria hoje? | C24: =Carteira!$G$9 | D24: DY por classe
B26: COMO NAVEGAR
B28: Parâmetros | C28: Todas as variáveis globais (aporte, perfil, P4, taxa) e o painel de cenários. | D28: células azuis
B29: Perfis | C29: Tabela de apoio do PROCV: % e aporte de cada perfil de investidor. | D29: coluna % do aporte
B30: Simulador | C30: P3: dividendos ano a ano (2 a 30 anos) e valor presente. P4: patrimônio com VF. | D30: só leitura (mexa em Parâmetros)
B31: Carteira | C31: Divisão do aporte por classe de FII e renda mensal estimada. | D31: % e DY das classes
B32: Instruções | C32: Este guia: respostas, passos, intervalos nomeados e checklist. | D32: —
B34: OS CINCO PASSOS DO DESAFIO (como eu construí esta planilha)
B36: 1) Base da tabela — defina as colunas do simulador (ano, aporte, rendimento, dividendos, valor presente) e as variáveis globais.
B37: 2) Simulador de patrimônio — patrimônio = VF(taxa mensal; anos×12; −aporte mensal; −aporte inicial; 0).
B38: 3) Simulador de cenários — projete 2 a 30 anos e traga os valores a valor presente (1/(1+i)^n).
B39: 4) Variáveis globais e intervalos nomeados — nomeie as células-chave (RentabilidadeAnual, AporteMensal, P4...) e use os nomes nas fórmulas.
B40: 5) Perfil do investidor com PROCV — tabela de apoio (aba Perfis) + PROCV(Perfil;TabelaPerfis;3;0) para dividir o aporte.
B41: ＋) Uniformidade visual e fundos — cores por função (entrada/cálculo), faixas, zebra, formatos monetários e gráficos.
B43: INTERVALOS NOMEADOS (Fórmulas ▸ Gerenciador de Nomes)
B44: Nome | C44: Aponta para | D44: Para que serve
B45: RentabilidadeAnual | C45: Parâmetros!C5 | D45: taxa anual usada no rendimento do principal
B46: TaxaMensal | C46: Parâmetros!C6 | D46: taxa mensal equivalente (VF)
B47: AporteInicial | C47: Parâmetros!C7 | D47: valor aplicado no mês zero
B48: AporteMensal | C48: Parâmetros!C8 | D48: aporte mensal cheio (antes do perfil)
...

Sheet Parâmetros
B2: PARÂMETROS GLOBAIS • edite as células azuis
B3: Todas as outras abas leem estes valores por intervalos nomeados (Ex.: RentabilidadeAnual = C5). Mudou aqui, mudou em tudo.
B5: Rentabilidade anual esperada dos FIIs | C5: 0.1 | D5: Retorno total esperado (valorização + reinvestimento). 10% a.a. é uma hipótese usual para simulações de longo prazo — ajuste ao seu cenário.
B6: Taxa mensal equivalente (calculada) | C6: =(1+RentabilidadeAnual)^(1/12)-1 | D6: Taxa mensal equivalente à anual (juros compostos). É a taxa usada pelo VF.
B7: Aporte inicial (R$) | C7: 1000 | D7: Valor aplicado no mês zero, antes dos aportes mensais.
B8: Aporte mensal cheio (R$) | C8: 450 | D8: Quanto você separa por mês. A divisão por perfil é feita pelo PROCV (aba Perfis).
B9: Cotação do FII no mercado (R$) | C9: 100 | D9: Preço unitário de referência para estimar quantas cotas o aporte compra.
B10: Dividend Yield mensal médio esperado (%) | C10: 0.008 | D10: Rendimento mensal estimado sobre o patrimônio (0,80% ao mês ≈ 10% ao ano). FIIs não têm rendimento fixo: varia mês a mês.
B11: Perfil do investidor | C11: Moderado | D11: Conservador (15% do aporte) • Moderado (70%) • Agressivo (100%). A coluna % do aporte fica na aba Perfis e é lida aqui pelo PROCV.
B12: Percentual do aporte investido em FIIs — variável (P4) | C12: 0.85 | D12: Parte do aporte que entra nos FIIs agora; o restante fica na RESERVA DE OPORTUNIDADE (caixa) para comprar em quedas. Teste com responsabilidade.
B13: Salário mínimo vigente (R$) — referência | C13: 1518 | D13: Usado como régua: quantos salários mínimos seus dividendos pagariam por mês.
B16: SIMULADOR DE CENÁRIOS • 3 eixos: horizonte de 2 a 30 anos, Dividend Yield e rentabilidade
B17: Horizonte do cenário (anos) | C17: 10 | D17: Ande de 2 a 30 anos. O Simulador mostra a coluna de dividendos de cada ano e o resumo do ano escolhido.
B18: Dividend Yield mensal do cenário (%) | C18: =DividendYield | D18: Eixo 1: quanto o FII distribui por mês. O Simulador projeta os dividendos com ele.
B19: Rentabilidade anual do cenário (%) | C19: =RentabilidadeAnual | D19: Eixo 2: taxa de desconto / retorno esperado do cenário. É a taxa do VF (patrimônio).
B20: Taxa mensal do cenário (calculada) | C20: =(1+CenarioTaxa)^(1/12)-1 | D20: Usada em todos os cálculos mensais do cenário (VF e valor presente).
B21: Reserva de oportunidade investida no início? (S/N) | C21: N | D21: Marcar S só faz sentido se você realmente guarda dinheiro novo para as quedas. O ganho da reserva aparece no Simulador (P4).
B22: Os valores de partida espelham os parâmetros globais — sobrescreva para testar hipóteses.
B24: Legenda: fundo azul = célula de entrada (mude aqui) • fundo verde-claro = cálculo automático

Sheet Perfis
B2: PERFIS DE INVESTIDOR • tabela de apoio do PROCV
B3: Intervalo nomeado TabelaPerfis = B4:D7. O PROCV busca o aporte mensal já filtrado pelo perfil (coluna 3 da tabela).
B4: Perfil de investidor | C4: % do aporte | D4: Aporte mensal do perfil (R$) | E4: Aporte investido após P4 (R$) | F4: Reserva de oportunidade (R$/mês) | G4: Diretriz
B5: Conservador | C5: 0.15 | D5: =AporteMensal*$C5 | E5: =$D5*PercentualInvestido | F5: =$D5-$E5 | G5: Preserva capital: prioriza FIIs de papel (CRI) e mantém reserva maior.
B6: Moderado | C6: 0.7 | D6: =AporteMensal*$C6 | E6: =$D6*PercentualInvestido | F6: =$D6-$E6 | G6: Equilibra tijolo e papel; usa a reserva para as quedas.
B7: Agressivo | C7: 1 | D7: =AporteMensal*$C7 | E7: =$D7*PercentualInvestido | F7: =$D7-$E7 | G7: Foca em tijolo/híbridos e reinveste praticamente todo o aporte.
B10: (P4) DIVISÃO DO APORTE POR PERFIL — exemplo numérico ao vivo
B11: Aporte mensal cheio (Parâmetros) | C11: =AporteMensal | D11: Comece pelo aporte cheio do mês.
B12: Aporte do perfil — PROCV(TabelaPerfis; 3) | C12: =VLOOKUP(Perfil,TabelaPerfis,3,0) | D12: O PROCV usa o intervalo nomeado TabelaPerfis: troca de perfil ⇒ troca o valor.
B13: → Investido agora nos FIIs (× P4) | C13: =C12*PercentualInvestido | D13: O percentual investido vem da variável P4 (Parâmetros C12).
B14: → Reserva de oportunidade (fica em caixa) | C14: =C12-C13 | D14: A reserva só entra no cálculo se você marcar S em Parâmetros (C21).
B16: Troque o perfil em Parâmetros (C11): esta tabela, o Simulador e a Carteira recalculam sozinhos — é o PROCV trabalhando.

Sheet Simulador
B2: SIMULADOR DE INVESTIMENTOS EM FIIs
B3: Passo 3 (dividendos ano a ano) + Passo 4 (patrimônio com VF) + perfil do investidor via PROCV + reserva de oportunidade. Edite tudo na aba Parâmetros.
B5: FILTRO DO PERFIL (Passo 4 — PROCV) | E5: RESUMO DOS PARÂMETROS DO CENÁRIO
B6: Perfil selecionado (Parâmetros C11) | C6: =Perfil | E6: Valor aplicado no início (R$) | F6: =AporteInicial
B7: Aporte mensal do perfil — PROCV(TabelaPerfis; 3) | C7: =VLOOKUP(Perfil,TabelaPerfis,3,0) | E7: Horizonte do cenário (anos) | F7: =CenarioAnos
B8: Percentual investido em FIIs (variável P4) | C8: =PercentualInvestido | E8: Rentabilidade anual do cenário | F8: =CenarioTaxa
B9: Aporte mensal investido em FIIs (base de tudo) | C9: =$C$7*$C$8 | E9: Dividend Yield mensal do cenário | F9: =CenarioDY
B10: Reserva de oportunidade (mensal) | C10: =$C$7-$C$9 | E10: Cotação do FII (R$) | F10: =ValorFII
B11: Reserva acumulada em 12 meses (envelope) | C11: =$C$10*12 | E11: Cotas compradas por mês (aprox.) | F11: =ROUNDDOWN($C$9/ValorFII,0)
B12: Reserva de oportunidade é investida? (S/N) | C12: =UsarReserva
B13: Envelope investido no início (N ⇒ R$ 0) | C13: =IF(UsarReserva="S",$C$11,0)
B14: Aporte inicial investido (× P4) | C14: =AporteInicial*$C$8
B15: P3 • SIMULADOR DE DIVIDENDOS POR HORIZONTE — 2 a 30 anos
B16: Ano do horizonte | C16: Aportes do ano (R$) | D16: Patrimônio estimado no fim do ano (R$) | E16: Dividendos do ano (R$) | F16: Dividendos acumulados (R$) | G16: Fator de desconto 1/(1+i)^n | H16: Dividendos do ano a valor presente | I16: Dividendos acumulados a valor presente | K16: RESUMO DO CENÁRIO (P3)
B17: 1 | C17: =IF($B17<=CenarioAnos,AporteInvestido*12,0)+IF($B17=1,AporteInicialInvestido,0) | D17: =IF($B17<=CenarioAnos,SUMPRODUCT((Anos<=$B17)*Aportes*(1+RentabilidadeAnual)^($B17-Anos)),0) | E17: =D17*((1+CenarioDY)^12-1) | F17: =SUM($E$17:E17) | G17: =1/(1+CenarioTaxa)^$B17 | H17: =E17*G17 | I17: =SUM($H$17:H17) | K17: Horizonte selecionado (anos) | L17: =CenarioAnos
B18: 2 | C18: =IF($B18<=CenarioAnos,AporteInvestido*12,0)+IF($B18=1,AporteInicialInvestido,0) | D18: =IF($B18<=CenarioAnos,SUMPRODUCT((Anos<=$B18)*Aportes*(1+RentabilidadeAnual)^($B18-Anos)),0) | E18: =D18*((1+CenarioDY)^12-1) | F18: =SUM($E$17:E18) | G18: =1/(1+CenarioTaxa)^$B18 | H18: =E18*G18 | I18: =SUM($H$17:H18) | K18: Aporte mensal investido (R$) | L18: =AporteInvestido
B19: 3 | C19: =IF($B19<=CenarioAnos,AporteInvestido*12,0)+IF($B19=1,AporteInicialInvestido,0) | D19: =IF($B19<=CenarioAnos,SUMPRODUCT((Anos<=$B19)*Aportes*(1+RentabilidadeAnual)^($B19-Anos)),0) | E19: =D19*((1+CenarioDY)^12-1) | F19: =SUM($E$17:E19) | G19: =1/(1+CenarioTaxa)^$B19 | H19: =E19*G19 | I19: =SUM($H$17:H19) | K19: Aporte inicial investido (R$) | L19: =AporteInicialInvestido
B20: 4 | C20: =IF($B20<=CenarioAnos,AporteInvestido*12,0)+IF($B20=1,AporteInicialInvestido,0) | D20: =IF($B20<=CenarioAnos,SUMPRODUCT((Anos<=$B20)*Aportes*(1+RentabilidadeAnual)^($B20-Anos)),0) | E20: =D20*((1+CenarioDY)^12-1) | F20: =SUM($E$17:E20) | G20: =1/(1+CenarioTaxa)^$B20 | H20: =E20*G20 | I20: =SUM($H$17:H20) | K20: Total investido no horizonte (R$) | L20: =AporteInicialInvestido+AporteInvestido*12*CenarioAnos
B21: 5 | C21: =IF($B21<=CenarioAnos,AporteInvestido*12,0)+IF($B21=1,AporteInicialInvestido,0) | D21: =IF($B21<=CenarioAnos,SUMPRODUCT((Anos<=$B21)*Aportes*(1+RentabilidadeAnual)^($B21-Anos)),0) | E21: =D21*((1+CenarioDY)^12-1) | F21: =SUM($E$17:E21) | G21: =1/(1+CenarioTaxa)^$B21 | H21: =E21*G21 | I21: =SUM($H$17:H21) | K21: Dividendos do ano do horizonte — SOMASE | L21: =SUMIF(Anos,CenarioAnos,DividendosNoAno)
B22: 6 | C22: =IF($B22<=CenarioAnos,AporteInvestido*12,0)+IF($B22=1,AporteInicialInvestido,0) | D22: =IF($B22<=CenarioAnos,SUMPRODUCT((Anos<=$B22)*Aportes*(1+RentabilidadeAnual)^($B22-Anos)),0) | E22: =D22*((1+CenarioDY)^12-1) | F22: =SUM($E$17:E22) | G22: =1/(1+CenarioTaxa)^$B22 | H22: =E22*G22 | I22: =SUM($H$17:H22) | K22: Equivalente por mês (R$) | L22: =$L$21/12
B23: 7 | C23: =IF($B23<=CenarioAnos,AporteInvestido*12,0)+IF($B23=1,AporteInicialInvestido,0) | D23: =IF($B23<=CenarioAnos,SUMPRODUCT((Anos<=$B23)*Aportes*(1+RentabilidadeAnual)^($B23-Anos)),0) | E23: =D23*((1+CenarioDY)^12-1) | F23: =SUM($E$17:E23) | G23: =1/(1+CenarioTaxa)^$B23 | H23: =E23*G23 | I23: =SUM($H$17:H23) | K23: Salários mínimos por mês pagos pelos dividendos | L23: =$L$22/SalarioMinimo
B24: 8 | C24: =IF($B24<=CenarioAnos,AporteInvestido*12,0)+IF($B24=1,AporteInicialInvestido,0) | D24: =IF($B24<=CenarioAnos,SUMPRODUCT((Anos<=$B24)*Aportes*(1+RentabilidadeAnual)^($B24-Anos)),0) | E24: =D24*((1+CenarioDY)^12-1) | F24: =SUM($E$17:E24) | G24: =1/(1+CenarioTaxa)^$B24 | H24: =E24*G24 | I24: =SUM($H$17:H24) | K24: Dividendos do horizonte a valor presente — SOMARPRODUTO | L24: =SUMPRODUCT(DividendosNoAno,FatorDesconto)
B25: 9 | C25: =IF($B25<=CenarioAnos,AporteInvestido*12,0)+IF($B25=1,AporteInicialInvestido,0) | D25: =IF($B25<=CenarioAnos,SUMPRODUCT((Anos<=$B25)*Aportes*(1+RentabilidadeAnual)^($B25-Anos)),0) | E25: =D25*((1+CenarioDY)^12-1) | F25: =SUM($E$17:E25) | G25: =1/(1+CenarioTaxa)^$B25 | H25: =E25*G25 | I25: =SUM($H$17:H25) | K25: Dividendos acumulados durante todo o horizonte | L25: =SUM(DividendosNoAno)
B26: 10 | C26: =IF($B26<=CenarioAnos,AporteInvestido*12,0)+IF($B26=1,AporteInicialInvestido,0) | D26: =IF($B26<=CenarioAnos,SUMPRODUCT((Anos<=$B26)*Aportes*(1+RentabilidadeAnual)^($B26-Anos)),0) | E26: =D26*((1+CenarioDY)^12-1) | F26: =SUM($E$17:E26) | G26: =1/(1+CenarioTaxa)^$B26 | H26: =E26*G26 | I26: =SUM($H$17:H26) | K26: Dividendos acumulados até o ano do horizonte | L26: =SUMIF(Anos,CenarioAnos,DividendosAcumulados)
B27: 11 | C27: =IF($B27<=CenarioAnos,AporteInvestido*12,0)+IF($B27=1,AporteInicialInvestido,0) | D27: =IF($B27<=CenarioAnos,SUMPRODUCT((Anos<=$B27)*Aportes*(1+RentabilidadeAnual)^($B27-Anos)),0) | E27: =D27*((1+CenarioDY)^12-1) | F27: =SUM($E$17:E27) | G27: =1/(1+CenarioTaxa)^$B27 | H27: =E27*G27 | I27: =SUM($H$17:H27) | K27: Patrimônio estimado no fim do ano do horizonte | L27: =SUMIF(Anos,CenarioAnos,PatrimonioEstimado)
B28: 12 | C28: =IF($B28<=CenarioAnos,AporteInvestido*12,0)+IF($B28=1,AporteInicialInvestido,0) | D28: =IF($B28<=CenarioAnos,SUMPRODUCT((Anos<=$B28)*Aportes*(1+RentabilidadeAnual)^($B28-Anos)),0) | E28: =D28*((1+CenarioDY)^12-1) | F28: =SUM($E$17:E28) | G28: =1/(1+CenarioTaxa)^$B28 | H28: =E28*G28 | I28: =SUM($H$17:H28)
B29: 13 | C29: =IF($B29<=CenarioAnos,AporteInvestido*12,0)+IF($B29=1,AporteInicialInvestido,0) | D29: =IF($B29<=CenarioAnos,SUMPRODUCT((Anos<=$B29)*Aportes*(1+RentabilidadeAnual)^($B29-Anos)),0) | E29: =D29*((1+CenarioDY)^12-1) | F29: =SUM($E$17:E29) | G29: =1/(1+CenarioTaxa)^$B29 | H29: =E29*G29 | I29: =SUM($H$17:H29) | K29: Teste 2, 5, 10, 20 e 30 anos em Parâmetros (C17) e compare os totais acima.
B30: 14 | C30: =IF($B30<=CenarioAnos,AporteInvestido*12,0)+IF($B30=1,AporteInicialInvestido,0) | D30: =IF($B30<=CenarioAnos,SUMPRODUCT((Anos<=$B30)*Aportes*(1+RentabilidadeAnual)^($B30-Anos)),0) | E30: =D30*((1+CenarioDY)^12-1) | F30: =SUM($E$17:E30) | G30: =1/(1+CenarioTaxa)^$B30 | H30: =E30*G30 | I30: =SUM($H$17:H30)
B31: 15 | C31: =IF($B31<=CenarioAnos,AporteInvestido*12,0)+IF($B31=1,AporteInicialInvestido,0) | D31: =IF($B31<=CenarioAnos,SUMPRODUCT((Anos<=$B31)*Aportes*(1+RentabilidadeAnual)^($B31-Anos)),0) | E31: =D31*((1+CenarioDY)^12-1) | F31: =SUM($E$17:E31) | G31: =1/(1+CenarioTaxa)^$B31 | H31: =E31*G31 | I31: =SUM($H$17:H31)
B32: 16 | C32: =IF($B32<=CenarioAnos,AporteInvestido*12,0)+IF($B32=1,AporteInicialInvestido,0) | D32: =IF($B32<=CenarioAnos,SUMPRODUCT((Anos<=$B32)*Aportes*(1+RentabilidadeAnual)^($B32-Anos)),0) | E32: =D32*((1+CenarioDY)^12-1) | F32: =SUM($E$17:E32) | G32: =1/(1+CenarioTaxa)^$B32 | H32: =E32*G32 | I32: =SUM($H$17:H32)
B33: 17 | C33: =IF($B33<=CenarioAnos,AporteInvestido*12,0)+IF($B33=1,AporteInicialInvestido,0) | D33: =IF($B33<=CenarioAnos,SUMPRODUCT((Anos<=$B33)*Aportes*(1+RentabilidadeAnual)^($B33-Anos)),0) | E33: =D33*((1+CenarioDY)^12-1) | F33: =SUM($E$17:E33) | G33: =1/(1+CenarioTaxa)^$B33 | H33: =E33*G33 | I33: =SUM($H$17:H33)
B34: 18 | C34: =IF($B34<=CenarioAnos,AporteInvestido*12,0)+IF($B34=1,AporteInicialInvestido,0) | D34: =IF($B34<=CenarioAnos,SUMPRODUCT((Anos<=$B34)*Aportes*(1+RentabilidadeAnual)^($B34-Anos)),0) | E34: =D34*((1+CenarioDY)^12-1) | F34: =SUM($E$17:E34) | G34: =1/(1+CenarioTaxa)^$B34 | H34: =E34*G34 | I34: =SUM($H$17:H34)
B35: 19 | C35: =IF($B35<=CenarioAnos,AporteInvestido*12,0)+IF($B35=1,AporteInicialInvestido,0) | D35: =IF($B35<=CenarioAnos,SUMPRODUCT((Anos<=$B35)*Aportes*(1+RentabilidadeAnual)^($B35-Anos)),0) | E35: =D35*((1+CenarioDY)^12-1) | F35: =SUM($E$17:E35) | G35: =1/(1+CenarioTaxa)^$B35 | H35: =E35*G35 | I35: =SUM($H$17:H35)
B36: 20 | C36: =IF($B36<=CenarioAnos,AporteInvestido*12,0)+IF($B36=1,AporteInicialInvestido,0) | D36: =IF($B36<=CenarioAnos,SUMPRODUCT((Anos<=$B36)*Aportes*(1+RentabilidadeAnual)^($B36-Anos)),0) | E36: =D36*((1+CenarioDY)^12-1) | F36: =SUM($E$17:E36) | G36: =1/(1+CenarioTaxa)^$B36 | H36: =E36*G36 | I36: =SUM($H$17:H36)
B37: 21 | C37: =IF($B37<=CenarioAnos,AporteInvestido*12,0)+IF($B37=1,AporteInicialInvestido,0) | D37: =IF($B37<=CenarioAnos,SUMPRODUCT((Anos<=$B37)*Aportes*(1+RentabilidadeAnual)^($B37-Anos)),0) | E37: =D37*((1+CenarioDY)^12-1) | F37: =SUM($E$17:E37) | G37: =1/(1+CenarioTaxa)^$B37 | H37: =E37*G37 | I37: =SUM($H$17:H37)
B38: 22 | C38: =IF($B38<=CenarioAnos,AporteInvestido*12,0)+IF($B38=1,AporteInicialInvestido,0) | D38: =IF($B38<=CenarioAnos,SUMPRODUCT((Anos<=$B38)*Aportes*(1+RentabilidadeAnual)^($B38-Anos)),0) | E38: =D38*((1+CenarioDY)^12-1) | F38: =SUM($E$17:E38) | G38: =1/(1+CenarioTaxa)^$B38 | H38: =E38*G38 | I38: =SUM($H$17:H38)
B39: 23 | C39: =IF($B39<=CenarioAnos,AporteInvestido*12,0)+IF($B39=1,AporteInicialInvestido,0) | D39: =IF($B39<=CenarioAnos,SUMPRODUCT((Anos<=$B39)*Aportes*(1+RentabilidadeAnual)^($B39-Anos)),0) | E39: =D39*((1+CenarioDY)^12-1) | F39: =SUM($E$17:E39) | G39: =1/(1+CenarioTaxa)^$B39 | H39: =E39*G39 | I39: =SUM($H$17:H39)
B40: 24 | C40: =IF($B40<=CenarioAnos,AporteInvestido*12,0)+IF($B40=1,AporteInicialInvestido,0) | D40: =IF($B40<=CenarioAnos,SUMPRODUCT((Anos<=$B40)*Aportes*(1+RentabilidadeAnual)^($B40-Anos)),0) | E40: =D40*((1+CenarioDY)^12-1) | F40: =SUM($E$17:E40) | G40: =1/(1+CenarioTaxa)^$B40 | H40: =E40*G40 | I40: =SUM($H$17:H40)
B41: 25 | C41: =IF($B41<=CenarioAnos,AporteInvestido*12,0)+IF($B41=1,AporteInicialInvestido,0) | D41: =IF($B41<=CenarioAnos,SUMPRODUCT((Anos<=$B41)*Aportes*(1+RentabilidadeAnual)^($B41-Anos)),0) | E41: =D41*((1+CenarioDY)^12-1) | F41: =SUM($E$17:E41) | G41: =1/(1+CenarioTaxa)^$B41 | H41: =E41*G41 | I41: =SUM($H$17:H41)
... B46: 30 | C46: =IF($B46<=CenarioAnos,AporteInvestido*12,0)+IF($B46=1,AporteInicialInvestido,0) | D46: =IF($B46<=CenarioAnos,SUMPRODUCT((Anos<=$B46)*Aportes*(1+RentabilidadeAnual)^($B46-Anos)),0) | E46: =D46*((1+CenarioDY)^12-1) | F46: =SUM($E$17:E46) | G46: =1/(1+CenarioTaxa)^$B46 | H46: =E46*G46 | I46: =SUM($H$17:H46)
...

Sheet Carteira
B2: CARTEIRA — DIVISÃO DO APORTE POR CLASSE DE FII (Passo 5)
B3: O aporte do perfil (PROCV) é dividido entre as classes. Os dividendos usam o Dividend Yield de cada classe — a estimativa serve para dimensionar metas, não é garantia.
B5: Classe de FII | C5: % do aporte | D5: Aporte inicial (R$) | E5: Aporte mensal (R$) | F5: DY mensal | G5: Dividendos estimados (R$/mês) | H5: Conferência: % da carteira | J5: APOIO — PROCV
B6: FIIs de Tijolo (shoppings, galpões, lajes) | C6: 0.6 | D6: =AporteInicial*$C6*PercentualInvestido | E6: =$K$9*$C6 | F6: 0.006 | G6: =$E6*$F6 | H6: =IF(SUM($E$6:$E$8)=0,0,$E6/SUM($E$6:$E$8)) | J6: Perfil selecionado (Parâmetros) | K6: =Perfil
B7: FIIs de Papel (CRI, recebíveis) | C7: 0.3 | D7: =AporteInicial*$C7*PercentualInvestido | E7: =$K$9*$C7 | F7: 0.01 | G7: =$E7*$F7 | H7: =IF(SUM($E$6:$E$8)=0,0,$E7/SUM($E$6:$E$8)) | J7: Aporte mensal do perfil — PROCV | K7: =VLOOKUP(Perfil,TabelaPerfis,3,0)
B8: Híbridos e Fundos de Fundos | C8: 0.1 | D8: =AporteInicial*$C8*PercentualInvestido | E8: =$K$9*$C8 | F8: 0.008 | G8: =$E8*$F8 | H8: =IF(SUM($E$6:$E$8)=0,0,$E8/SUM($E$6:$E$8)) | J8: Percentual investido em FIIs (P4) | K8: =PercentualInvestido
B9: TOTAL DA CARTEIRA | C9: =SUM($C$6:$C$8) | D9: =SUM($D$6:$D$8) | E9: =SUM($E$6:$E$8) | F9: =SUMPRODUCT($F$6:$F$8,$E$6:$E$8)/$E$9 | G9: =SUM($G$6:$G$8) | H9: =SUM($H$6:$H$8) | J9: Aporte mensal investido (base da divisão) | K9: =$K$7*$K$8
J10: Reserva de oportunidade mensal | K10: =$K$7-$K$9
B11: DY por classe: tijolo ≈ 0,60%/mês • papel ≈ 1,00%/mês • híbridos ≈ 0,80%/mês (médias de referência — ajuste na coluna DY). | J11: Reserva acumulada em 12 meses | K11: =$K$10*12
B12: Dividendos de FIIs variam todo mês e não são garantidos: use a estimativa para planejar metas, e reinvestir os proventos para acelerar os juros compostos. | J12: Cotas compradas por mês (na cotação atual) | K12: =ROUNDDOWN($K$9/ValorFII,0)
J13: Dividendos estimados da carteira por mês | K13: =$G$9
B14: Legenda: fundo azul = entrada (% e DY das classes) • fundo verde-claro = cálculo automático
